{
 "cells": [
  {
   "cell_type": "code",
   "execution_count": 9,
   "metadata": {},
   "outputs": [],
   "source": [
    "import transformers\n",
    "import torch\n",
    "# from transformers import LlamaTokenizer, LlamaForCausalLM\n",
    "from datasets import load_dataset"
   ]
  },
  {
   "cell_type": "code",
   "execution_count": null,
   "metadata": {},
   "outputs": [],
   "source": [
    "DEVICE = \"cuda\" if torch.cuda.is_available() else \"cpu\"\n",
    "DEVICE"
   ]
  },
  {
   "cell_type": "code",
   "execution_count": null,
   "metadata": {},
   "outputs": [],
   "source": [
    "model_path = 'openlm-research/open_llama_3b'\n",
    "\n",
    "tokenizer = transformers.LlamaTokenizer.from_pretrained(model_path)\n",
    "model = transformers.LlamaForCausalLM.from_pretrained(\n",
    "    model_path, load_in_8bit=True, torch_dtype=torch.float16, device_map=\"auto\",\n",
    ")\n",
    "\n",
    "tokenizer.pad_token_id = (0)\n",
    "\n",
    "tokenizer.padding_side = \"left\""
   ]
  },
  {
   "cell_type": "code",
   "execution_count": 10,
   "metadata": {},
   "outputs": [
    {
     "name": "stdout",
     "output_type": "stream",
     "text": [
      "Downloading and preparing dataset json/default to /Users/mac/.cache/huggingface/datasets/json/default-14d4689bfc193431/0.0.0/0f7e3662623656454fcd2b650f34e886a7db4b9104504885bd462096cc7a9f51...\n"
     ]
    },
    {
     "name": "stderr",
     "output_type": "stream",
     "text": [
      "Downloading data files: 100%|██████████| 1/1 [00:00<00:00, 1723.92it/s]\n",
      "Extracting data files: 100%|██████████| 1/1 [00:00<00:00, 401.75it/s]\n",
      "Generating train split: 0 examples [00:00, ? examples/s]Failed to read file '/Users/mac/Desktop/LLM-Sentimental-Analysis/data/processed_datasets/alpaca-news-sentiment-dataset.json' with error <class 'pyarrow.lib.ArrowInvalid'>: JSON parse error: Column(/input) changed from string to number in row 841\n",
      "                                                        \r"
     ]
    },
    {
     "ename": "DatasetGenerationError",
     "evalue": "An error occurred while generating the dataset",
     "output_type": "error",
     "traceback": [
      "\u001b[0;31m---------------------------------------------------------------------------\u001b[0m",
      "\u001b[0;31mJSONDecodeError\u001b[0m                           Traceback (most recent call last)",
      "File \u001b[0;32m~/opt/anaconda3/envs/main_env/lib/python3.10/site-packages/datasets/packaged_modules/json/json.py:152\u001b[0m, in \u001b[0;36mJson._generate_tables\u001b[0;34m(self, files)\u001b[0m\n\u001b[1;32m    151\u001b[0m     \u001b[39mwith\u001b[39;00m \u001b[39mopen\u001b[39m(file, encoding\u001b[39m=\u001b[39m\u001b[39m\"\u001b[39m\u001b[39mutf-8\u001b[39m\u001b[39m\"\u001b[39m) \u001b[39mas\u001b[39;00m f:\n\u001b[0;32m--> 152\u001b[0m         dataset \u001b[39m=\u001b[39m json\u001b[39m.\u001b[39;49mload(f)\n\u001b[1;32m    153\u001b[0m \u001b[39mexcept\u001b[39;00m json\u001b[39m.\u001b[39mJSONDecodeError:\n",
      "File \u001b[0;32m~/opt/anaconda3/envs/main_env/lib/python3.10/json/__init__.py:293\u001b[0m, in \u001b[0;36mload\u001b[0;34m(fp, cls, object_hook, parse_float, parse_int, parse_constant, object_pairs_hook, **kw)\u001b[0m\n\u001b[1;32m    276\u001b[0m \u001b[39m\"\"\"Deserialize ``fp`` (a ``.read()``-supporting file-like object containing\u001b[39;00m\n\u001b[1;32m    277\u001b[0m \u001b[39ma JSON document) to a Python object.\u001b[39;00m\n\u001b[1;32m    278\u001b[0m \n\u001b[0;32m   (...)\u001b[0m\n\u001b[1;32m    291\u001b[0m \u001b[39mkwarg; otherwise ``JSONDecoder`` is used.\u001b[39;00m\n\u001b[1;32m    292\u001b[0m \u001b[39m\"\"\"\u001b[39;00m\n\u001b[0;32m--> 293\u001b[0m \u001b[39mreturn\u001b[39;00m loads(fp\u001b[39m.\u001b[39;49mread(),\n\u001b[1;32m    294\u001b[0m     \u001b[39mcls\u001b[39;49m\u001b[39m=\u001b[39;49m\u001b[39mcls\u001b[39;49m, object_hook\u001b[39m=\u001b[39;49mobject_hook,\n\u001b[1;32m    295\u001b[0m     parse_float\u001b[39m=\u001b[39;49mparse_float, parse_int\u001b[39m=\u001b[39;49mparse_int,\n\u001b[1;32m    296\u001b[0m     parse_constant\u001b[39m=\u001b[39;49mparse_constant, object_pairs_hook\u001b[39m=\u001b[39;49mobject_pairs_hook, \u001b[39m*\u001b[39;49m\u001b[39m*\u001b[39;49mkw)\n",
      "File \u001b[0;32m~/opt/anaconda3/envs/main_env/lib/python3.10/json/__init__.py:346\u001b[0m, in \u001b[0;36mloads\u001b[0;34m(s, cls, object_hook, parse_float, parse_int, parse_constant, object_pairs_hook, **kw)\u001b[0m\n\u001b[1;32m    343\u001b[0m \u001b[39mif\u001b[39;00m (\u001b[39mcls\u001b[39m \u001b[39mis\u001b[39;00m \u001b[39mNone\u001b[39;00m \u001b[39mand\u001b[39;00m object_hook \u001b[39mis\u001b[39;00m \u001b[39mNone\u001b[39;00m \u001b[39mand\u001b[39;00m\n\u001b[1;32m    344\u001b[0m         parse_int \u001b[39mis\u001b[39;00m \u001b[39mNone\u001b[39;00m \u001b[39mand\u001b[39;00m parse_float \u001b[39mis\u001b[39;00m \u001b[39mNone\u001b[39;00m \u001b[39mand\u001b[39;00m\n\u001b[1;32m    345\u001b[0m         parse_constant \u001b[39mis\u001b[39;00m \u001b[39mNone\u001b[39;00m \u001b[39mand\u001b[39;00m object_pairs_hook \u001b[39mis\u001b[39;00m \u001b[39mNone\u001b[39;00m \u001b[39mand\u001b[39;00m \u001b[39mnot\u001b[39;00m kw):\n\u001b[0;32m--> 346\u001b[0m     \u001b[39mreturn\u001b[39;00m _default_decoder\u001b[39m.\u001b[39;49mdecode(s)\n\u001b[1;32m    347\u001b[0m \u001b[39mif\u001b[39;00m \u001b[39mcls\u001b[39m \u001b[39mis\u001b[39;00m \u001b[39mNone\u001b[39;00m:\n",
      "File \u001b[0;32m~/opt/anaconda3/envs/main_env/lib/python3.10/json/decoder.py:340\u001b[0m, in \u001b[0;36mJSONDecoder.decode\u001b[0;34m(self, s, _w)\u001b[0m\n\u001b[1;32m    339\u001b[0m \u001b[39mif\u001b[39;00m end \u001b[39m!=\u001b[39m \u001b[39mlen\u001b[39m(s):\n\u001b[0;32m--> 340\u001b[0m     \u001b[39mraise\u001b[39;00m JSONDecodeError(\u001b[39m\"\u001b[39m\u001b[39mExtra data\u001b[39m\u001b[39m\"\u001b[39m, s, end)\n\u001b[1;32m    341\u001b[0m \u001b[39mreturn\u001b[39;00m obj\n",
      "\u001b[0;31mJSONDecodeError\u001b[0m: Extra data: line 2 column 1 (char 214)",
      "\nDuring handling of the above exception, another exception occurred:\n",
      "\u001b[0;31mArrowInvalid\u001b[0m                              Traceback (most recent call last)",
      "File \u001b[0;32m~/opt/anaconda3/envs/main_env/lib/python3.10/site-packages/datasets/builder.py:1860\u001b[0m, in \u001b[0;36mArrowBasedBuilder._prepare_split_single\u001b[0;34m(self, gen_kwargs, fpath, file_format, max_shard_size, job_id)\u001b[0m\n\u001b[1;32m   1859\u001b[0m _time \u001b[39m=\u001b[39m time\u001b[39m.\u001b[39mtime()\n\u001b[0;32m-> 1860\u001b[0m \u001b[39mfor\u001b[39;00m _, table \u001b[39min\u001b[39;00m generator:\n\u001b[1;32m   1861\u001b[0m     \u001b[39mif\u001b[39;00m max_shard_size \u001b[39mis\u001b[39;00m \u001b[39mnot\u001b[39;00m \u001b[39mNone\u001b[39;00m \u001b[39mand\u001b[39;00m writer\u001b[39m.\u001b[39m_num_bytes \u001b[39m>\u001b[39m max_shard_size:\n",
      "File \u001b[0;32m~/opt/anaconda3/envs/main_env/lib/python3.10/site-packages/datasets/packaged_modules/json/json.py:155\u001b[0m, in \u001b[0;36mJson._generate_tables\u001b[0;34m(self, files)\u001b[0m\n\u001b[1;32m    154\u001b[0m     logger\u001b[39m.\u001b[39merror(\u001b[39mf\u001b[39m\u001b[39m\"\u001b[39m\u001b[39mFailed to read file \u001b[39m\u001b[39m'\u001b[39m\u001b[39m{\u001b[39;00mfile\u001b[39m}\u001b[39;00m\u001b[39m'\u001b[39m\u001b[39m with error \u001b[39m\u001b[39m{\u001b[39;00m\u001b[39mtype\u001b[39m(e)\u001b[39m}\u001b[39;00m\u001b[39m: \u001b[39m\u001b[39m{\u001b[39;00me\u001b[39m}\u001b[39;00m\u001b[39m\"\u001b[39m)\n\u001b[0;32m--> 155\u001b[0m     \u001b[39mraise\u001b[39;00m e\n\u001b[1;32m    156\u001b[0m \u001b[39m# If possible, parse the file as a list of json objects and exit the loop\u001b[39;00m\n",
      "File \u001b[0;32m~/opt/anaconda3/envs/main_env/lib/python3.10/site-packages/datasets/packaged_modules/json/json.py:131\u001b[0m, in \u001b[0;36mJson._generate_tables\u001b[0;34m(self, files)\u001b[0m\n\u001b[1;32m    130\u001b[0m \u001b[39mtry\u001b[39;00m:\n\u001b[0;32m--> 131\u001b[0m     pa_table \u001b[39m=\u001b[39m paj\u001b[39m.\u001b[39;49mread_json(\n\u001b[1;32m    132\u001b[0m         io\u001b[39m.\u001b[39;49mBytesIO(batch), read_options\u001b[39m=\u001b[39;49mpaj\u001b[39m.\u001b[39;49mReadOptions(block_size\u001b[39m=\u001b[39;49mblock_size)\n\u001b[1;32m    133\u001b[0m     )\n\u001b[1;32m    134\u001b[0m     \u001b[39mbreak\u001b[39;00m\n",
      "File \u001b[0;32m~/opt/anaconda3/envs/main_env/lib/python3.10/site-packages/pyarrow/_json.pyx:258\u001b[0m, in \u001b[0;36mpyarrow._json.read_json\u001b[0;34m()\u001b[0m\n",
      "File \u001b[0;32m~/opt/anaconda3/envs/main_env/lib/python3.10/site-packages/pyarrow/error.pxi:144\u001b[0m, in \u001b[0;36mpyarrow.lib.pyarrow_internal_check_status\u001b[0;34m()\u001b[0m\n",
      "File \u001b[0;32m~/opt/anaconda3/envs/main_env/lib/python3.10/site-packages/pyarrow/error.pxi:100\u001b[0m, in \u001b[0;36mpyarrow.lib.check_status\u001b[0;34m()\u001b[0m\n",
      "\u001b[0;31mArrowInvalid\u001b[0m: JSON parse error: Column(/input) changed from string to number in row 841",
      "\nThe above exception was the direct cause of the following exception:\n",
      "\u001b[0;31mDatasetGenerationError\u001b[0m                    Traceback (most recent call last)",
      "\u001b[1;32m/Users/mac/Desktop/LLM-Sentimental-Analysis/notebooks/prototype.ipynb Cell 4\u001b[0m in \u001b[0;36m<cell line: 2>\u001b[0;34m()\u001b[0m\n\u001b[1;32m      <a href='vscode-notebook-cell:/Users/mac/Desktop/LLM-Sentimental-Analysis/notebooks/prototype.ipynb#W4sZmlsZQ%3D%3D?line=0'>1</a>\u001b[0m data_path \u001b[39m=\u001b[39m \u001b[39m\"\u001b[39m\u001b[39m/Users/mac/Desktop/LLM-Sentimental-Analysis/data/processed_datasets/alpaca-news-sentiment-dataset.json\u001b[39m\u001b[39m\"\u001b[39m\n\u001b[0;32m----> <a href='vscode-notebook-cell:/Users/mac/Desktop/LLM-Sentimental-Analysis/notebooks/prototype.ipynb#W4sZmlsZQ%3D%3D?line=1'>2</a>\u001b[0m data \u001b[39m=\u001b[39m load_dataset(\u001b[39m\"\u001b[39;49m\u001b[39mjson\u001b[39;49m\u001b[39m\"\u001b[39;49m, data_files\u001b[39m=\u001b[39;49mdata_path)\n",
      "File \u001b[0;32m~/opt/anaconda3/envs/main_env/lib/python3.10/site-packages/datasets/load.py:1782\u001b[0m, in \u001b[0;36mload_dataset\u001b[0;34m(path, name, data_dir, data_files, split, cache_dir, features, download_config, download_mode, verification_mode, ignore_verifications, keep_in_memory, save_infos, revision, use_auth_token, task, streaming, num_proc, **config_kwargs)\u001b[0m\n\u001b[1;32m   1779\u001b[0m try_from_hf_gcs \u001b[39m=\u001b[39m path \u001b[39mnot\u001b[39;00m \u001b[39min\u001b[39;00m _PACKAGED_DATASETS_MODULES\n\u001b[1;32m   1781\u001b[0m \u001b[39m# Download and prepare data\u001b[39;00m\n\u001b[0;32m-> 1782\u001b[0m builder_instance\u001b[39m.\u001b[39;49mdownload_and_prepare(\n\u001b[1;32m   1783\u001b[0m     download_config\u001b[39m=\u001b[39;49mdownload_config,\n\u001b[1;32m   1784\u001b[0m     download_mode\u001b[39m=\u001b[39;49mdownload_mode,\n\u001b[1;32m   1785\u001b[0m     verification_mode\u001b[39m=\u001b[39;49mverification_mode,\n\u001b[1;32m   1786\u001b[0m     try_from_hf_gcs\u001b[39m=\u001b[39;49mtry_from_hf_gcs,\n\u001b[1;32m   1787\u001b[0m     num_proc\u001b[39m=\u001b[39;49mnum_proc,\n\u001b[1;32m   1788\u001b[0m )\n\u001b[1;32m   1790\u001b[0m \u001b[39m# Build dataset for splits\u001b[39;00m\n\u001b[1;32m   1791\u001b[0m keep_in_memory \u001b[39m=\u001b[39m (\n\u001b[1;32m   1792\u001b[0m     keep_in_memory \u001b[39mif\u001b[39;00m keep_in_memory \u001b[39mis\u001b[39;00m \u001b[39mnot\u001b[39;00m \u001b[39mNone\u001b[39;00m \u001b[39melse\u001b[39;00m is_small_dataset(builder_instance\u001b[39m.\u001b[39minfo\u001b[39m.\u001b[39mdataset_size)\n\u001b[1;32m   1793\u001b[0m )\n",
      "File \u001b[0;32m~/opt/anaconda3/envs/main_env/lib/python3.10/site-packages/datasets/builder.py:872\u001b[0m, in \u001b[0;36mDatasetBuilder.download_and_prepare\u001b[0;34m(self, output_dir, download_config, download_mode, verification_mode, ignore_verifications, try_from_hf_gcs, dl_manager, base_path, use_auth_token, file_format, max_shard_size, num_proc, storage_options, **download_and_prepare_kwargs)\u001b[0m\n\u001b[1;32m    870\u001b[0m     \u001b[39mif\u001b[39;00m num_proc \u001b[39mis\u001b[39;00m \u001b[39mnot\u001b[39;00m \u001b[39mNone\u001b[39;00m:\n\u001b[1;32m    871\u001b[0m         prepare_split_kwargs[\u001b[39m\"\u001b[39m\u001b[39mnum_proc\u001b[39m\u001b[39m\"\u001b[39m] \u001b[39m=\u001b[39m num_proc\n\u001b[0;32m--> 872\u001b[0m     \u001b[39mself\u001b[39;49m\u001b[39m.\u001b[39;49m_download_and_prepare(\n\u001b[1;32m    873\u001b[0m         dl_manager\u001b[39m=\u001b[39;49mdl_manager,\n\u001b[1;32m    874\u001b[0m         verification_mode\u001b[39m=\u001b[39;49mverification_mode,\n\u001b[1;32m    875\u001b[0m         \u001b[39m*\u001b[39;49m\u001b[39m*\u001b[39;49mprepare_split_kwargs,\n\u001b[1;32m    876\u001b[0m         \u001b[39m*\u001b[39;49m\u001b[39m*\u001b[39;49mdownload_and_prepare_kwargs,\n\u001b[1;32m    877\u001b[0m     )\n\u001b[1;32m    878\u001b[0m \u001b[39m# Sync info\u001b[39;00m\n\u001b[1;32m    879\u001b[0m \u001b[39mself\u001b[39m\u001b[39m.\u001b[39minfo\u001b[39m.\u001b[39mdataset_size \u001b[39m=\u001b[39m \u001b[39msum\u001b[39m(split\u001b[39m.\u001b[39mnum_bytes \u001b[39mfor\u001b[39;00m split \u001b[39min\u001b[39;00m \u001b[39mself\u001b[39m\u001b[39m.\u001b[39minfo\u001b[39m.\u001b[39msplits\u001b[39m.\u001b[39mvalues())\n",
      "File \u001b[0;32m~/opt/anaconda3/envs/main_env/lib/python3.10/site-packages/datasets/builder.py:967\u001b[0m, in \u001b[0;36mDatasetBuilder._download_and_prepare\u001b[0;34m(self, dl_manager, verification_mode, **prepare_split_kwargs)\u001b[0m\n\u001b[1;32m    963\u001b[0m split_dict\u001b[39m.\u001b[39madd(split_generator\u001b[39m.\u001b[39msplit_info)\n\u001b[1;32m    965\u001b[0m \u001b[39mtry\u001b[39;00m:\n\u001b[1;32m    966\u001b[0m     \u001b[39m# Prepare split will record examples associated to the split\u001b[39;00m\n\u001b[0;32m--> 967\u001b[0m     \u001b[39mself\u001b[39;49m\u001b[39m.\u001b[39;49m_prepare_split(split_generator, \u001b[39m*\u001b[39;49m\u001b[39m*\u001b[39;49mprepare_split_kwargs)\n\u001b[1;32m    968\u001b[0m \u001b[39mexcept\u001b[39;00m \u001b[39mOSError\u001b[39;00m \u001b[39mas\u001b[39;00m e:\n\u001b[1;32m    969\u001b[0m     \u001b[39mraise\u001b[39;00m \u001b[39mOSError\u001b[39;00m(\n\u001b[1;32m    970\u001b[0m         \u001b[39m\"\u001b[39m\u001b[39mCannot find data file. \u001b[39m\u001b[39m\"\u001b[39m\n\u001b[1;32m    971\u001b[0m         \u001b[39m+\u001b[39m (\u001b[39mself\u001b[39m\u001b[39m.\u001b[39mmanual_download_instructions \u001b[39mor\u001b[39;00m \u001b[39m\"\u001b[39m\u001b[39m\"\u001b[39m)\n\u001b[1;32m    972\u001b[0m         \u001b[39m+\u001b[39m \u001b[39m\"\u001b[39m\u001b[39m\\n\u001b[39;00m\u001b[39mOriginal error:\u001b[39m\u001b[39m\\n\u001b[39;00m\u001b[39m\"\u001b[39m\n\u001b[1;32m    973\u001b[0m         \u001b[39m+\u001b[39m \u001b[39mstr\u001b[39m(e)\n\u001b[1;32m    974\u001b[0m     ) \u001b[39mfrom\u001b[39;00m \u001b[39mNone\u001b[39m\n",
      "File \u001b[0;32m~/opt/anaconda3/envs/main_env/lib/python3.10/site-packages/datasets/builder.py:1749\u001b[0m, in \u001b[0;36mArrowBasedBuilder._prepare_split\u001b[0;34m(self, split_generator, file_format, num_proc, max_shard_size)\u001b[0m\n\u001b[1;32m   1747\u001b[0m job_id \u001b[39m=\u001b[39m \u001b[39m0\u001b[39m\n\u001b[1;32m   1748\u001b[0m \u001b[39mwith\u001b[39;00m pbar:\n\u001b[0;32m-> 1749\u001b[0m     \u001b[39mfor\u001b[39;00m job_id, done, content \u001b[39min\u001b[39;00m \u001b[39mself\u001b[39m\u001b[39m.\u001b[39m_prepare_split_single(\n\u001b[1;32m   1750\u001b[0m         gen_kwargs\u001b[39m=\u001b[39mgen_kwargs, job_id\u001b[39m=\u001b[39mjob_id, \u001b[39m*\u001b[39m\u001b[39m*\u001b[39m_prepare_split_args\n\u001b[1;32m   1751\u001b[0m     ):\n\u001b[1;32m   1752\u001b[0m         \u001b[39mif\u001b[39;00m done:\n\u001b[1;32m   1753\u001b[0m             result \u001b[39m=\u001b[39m content\n",
      "File \u001b[0;32m~/opt/anaconda3/envs/main_env/lib/python3.10/site-packages/datasets/builder.py:1892\u001b[0m, in \u001b[0;36mArrowBasedBuilder._prepare_split_single\u001b[0;34m(self, gen_kwargs, fpath, file_format, max_shard_size, job_id)\u001b[0m\n\u001b[1;32m   1890\u001b[0m     \u001b[39mif\u001b[39;00m \u001b[39misinstance\u001b[39m(e, SchemaInferenceError) \u001b[39mand\u001b[39;00m e\u001b[39m.\u001b[39m__context__ \u001b[39mis\u001b[39;00m \u001b[39mnot\u001b[39;00m \u001b[39mNone\u001b[39;00m:\n\u001b[1;32m   1891\u001b[0m         e \u001b[39m=\u001b[39m e\u001b[39m.\u001b[39m__context__\n\u001b[0;32m-> 1892\u001b[0m     \u001b[39mraise\u001b[39;00m DatasetGenerationError(\u001b[39m\"\u001b[39m\u001b[39mAn error occurred while generating the dataset\u001b[39m\u001b[39m\"\u001b[39m) \u001b[39mfrom\u001b[39;00m \u001b[39me\u001b[39;00m\n\u001b[1;32m   1894\u001b[0m \u001b[39myield\u001b[39;00m job_id, \u001b[39mTrue\u001b[39;00m, (total_num_examples, total_num_bytes, writer\u001b[39m.\u001b[39m_features, num_shards, shard_lengths)\n",
      "\u001b[0;31mDatasetGenerationError\u001b[0m: An error occurred while generating the dataset"
     ]
    }
   ],
   "source": [
    "data_path = \"/Users/mac/Desktop/LLM-Sentimental-Analysis/data/processed_datasets/alpaca-news-sentiment-dataset.json\"\n",
    "data = load_dataset(\"json\", data_files=data_path, on_bad_lines='skip')"
   ]
  }
 ],
 "metadata": {
  "kernelspec": {
   "display_name": "main_env",
   "language": "python",
   "name": "main_env"
  },
  "language_info": {
   "codemirror_mode": {
    "name": "ipython",
    "version": 3
   },
   "file_extension": ".py",
   "mimetype": "text/x-python",
   "name": "python",
   "nbconvert_exporter": "python",
   "pygments_lexer": "ipython3",
   "version": "3.10.8"
  },
  "orig_nbformat": 4,
  "vscode": {
   "interpreter": {
    "hash": "a18dd08240dd2245c7aaa2dde8f5e96ef456027cdc8a595febcf82c3b0ce7a14"
   }
  }
 },
 "nbformat": 4,
 "nbformat_minor": 2
}
